<?xml version="1.0" encoding="UTF-8"?>
<!-- Generated by org.testng.reporters.JUnitXMLReporter -->
<testsuite hostname="DESKTOP-1ESRFEC" ignored="0" name="LoginTest" tests="2" failures="1" timestamp="28 Oct 2017 22:16:39 GMT" time="0.044" errors="0">
  <testcase name="loginTest" time="0.016" classname="Test_Listeners_testNG.LoginTest">
    <failure type="java.lang.Throwable" message="Multiple failures (2):nnFailure 1 of 2:njava.lang.AssertionError: expected [x] but found [a]
	at org.testng.Assert.fail(Assert.java:93)
	at org.testng.Assert.failNotEquals(Assert.java:512)
	at org.testng.Assert.assertEqualsImpl(Assert.java:134)
	at org.testng.Assert.assertEquals(Assert.java:115)
	at org.testng.Assert.assertEquals(Assert.java:189)
	at org.testng.Assert.assertEquals(Assert.java:199)
	at Test_Listeners_testNG.LoginTest.loginTest(LoginTest.java:14)
	at sun.reflect.NativeMethodAccessorImpl.invoke0(Native Method)
	at sun.reflect.NativeMethodAccessorImpl.invoke(Unknown Source)
	at sun.reflect.DelegatingMethodAccessorImpl.invoke(Unknown Source)
	at java.lang.reflect.Method.invoke(Unknown Source)
	at org.testng.internal.MethodInvocationHelper.invokeMethod(MethodInvocationHelper.java:108)
	at org.testng.internal.Invoker.invokeMethod(Invoker.java:669)
	at org.testng.internal.Invoker.invokeTestMethod(Invoker.java:877)
	at org.testng.internal.Invoker.invokeTestMethods(Invoker.java:1201)
	at org.testng.internal.TestMethodWorker.invokeTestMethods(TestMethodWorker.java:125)
	at org.testng.internal.TestMethodWorker.run(TestMethodWorker.java:109)
	at org.testng.TestRunner.privateRun(TestRunner.java:776)
	at org.testng.TestRunner.run(TestRunner.java:634)
	at org.testng.SuiteRunner.runTest(SuiteRunner.java:425)
	at org.testng.SuiteRunner.runSequentially(SuiteRunner.java:420)
	at org.testng.SuiteRunner.privateRun(SuiteRunner.java:385)
	at org.testng.SuiteRunner.run(SuiteRunner.java:334)
	at org.testng.SuiteRunnerWorker.runSuite(SuiteRunnerWorker.java:52)
	at org.testng.SuiteRunnerWorker.run(SuiteRunnerWorker.java:86)
	at org.testng.TestNG.runSuitesSequentially(TestNG.java:1318)
	at org.testng.TestNG.runSuitesLocally(TestNG.java:1243)
	at org.testng.TestNG.runSuites(TestNG.java:1161)
	at org.testng.TestNG.run(TestNG.java:1129)
	at org.testng.remote.AbstractRemoteTestNG.run(AbstractRemoteTestNG.java:114)
	at org.testng.remote.RemoteTestNG.initAndRun(RemoteTestNG.java:251)
	at org.testng.remote.RemoteTestNG.main(RemoteTestNG.java:77)
nnFailure 2 of 2:njava.lang.AssertionError: expected [c] but found [b]">
      <![CDATA[java.lang.Throwable: Multiple failures (2):nnFailure 1 of 2:njava.lang.AssertionError: expected [x] but found [a]
	at Test_Listeners_testNG.LoginTest.loginTest(LoginTest.java:14)
nnFailure 2 of 2:njava.lang.AssertionError: expected [c] but found [b]
	at Test_Listeners_testNG.LoginTest.loginTest(LoginTest.java:21)
... Removed 62 stack frames]]>
    </failure>
  </testcase> <!-- loginTest -->
  <testcase name="loginTest1" time="0.001" classname="Test_Listeners_testNG.LoginTest"/>
</testsuite> <!-- LoginTest -->
